{"name": "Ошибка 401 Unauthorized при попытке сделать заказ бургера неавторизованным пользователем", "status": "broken", "statusDetails": {"message": "NameError: name 'burger_api' is not defined", "trace": "@allure.step(\"Создание бургера из имеющихся ингредиентов\")\n    @pytest.fixture(scope='function')\n    def default_burger():\n>       ingredients = burger_api.get_ingredients().json()\nE       NameError: name 'burger_api' is not defined\n\ntests\\conftest.py:18: NameError"}, "description": "Неавторизованный пользователь не может сделать заказ бургера, возвращается ошибка 401 Unauthorized", "start": 1737281769668, "stop": 1737281769668, "uuid": "eb06b8ba-fa84-4992-888a-88747867ce5a", "historyId": "6d9e4a9cff6b3e758d747c7137a4054e", "testCaseId": "6d9e4a9cff6b3e758d747c7137a4054e", "fullName": "tests.test_create_order.TestCreateOrder#test_create_order_burger_not_auth_user_fail", "labels": [{"name": "parentSuite", "value": "tests"}, {"name": "suite", "value": "test_create_order"}, {"name": "subSuite", "value": "TestCreateOrder"}, {"name": "host", "value": "01ms32"}, {"name": "thread", "value": "8652-MainThread"}, {"name": "framework", "value": "pytest"}, {"name": "language", "value": "cpython3"}, {"name": "package", "value": "tests.test_create_order"}]}