{"name": "Ошибка 401 при получении списка заказов неавторизованным пользователем", "status": "broken", "statusDetails": {"message": "NameError: name 'burger_api' is not defined", "trace": "@allure.step(\"Создание бургера из имеющихся ингредиентов\")\n    @pytest.fixture(scope='function')\n    def default_burger():\n>       ingredients = burger_api.get_ingredients().json()\nE       NameError: name 'burger_api' is not defined\n\ntests\\conftest.py:18: NameError"}, "description": "Проверка возвращения ошибки 401 Unauthorized при попытке получения cписка заказов неавторизованным пользователем", "start": 1737281395019, "stop": 1737281395019, "uuid": "af012544-1f11-4f52-a944-6fc0f66e0487", "historyId": "6aec763dd17309031b2cb822ff31157d", "testCaseId": "6aec763dd17309031b2cb822ff31157d", "fullName": "tests.test_get_user_orders.TestGetUsersOrders#test_get_order_list_not_auth_user_fail", "labels": [{"name": "parentSuite", "value": "tests"}, {"name": "suite", "value": "test_get_user_orders"}, {"name": "subSuite", "value": "TestGetUsersOrders"}, {"name": "host", "value": "01ms32"}, {"name": "thread", "value": "10576-MainThread"}, {"name": "framework", "value": "pytest"}, {"name": "language", "value": "cpython3"}, {"name": "package", "value": "tests.test_get_user_orders"}]}